Workbook

Sheet Risk Weights
A1: Objective | B1: lambda (λ) | C1: iota (ι) | D1: epsilon (ε) | E1: assurance (a) | F1: localization (λ_s) | G1: Risk mass R | H1: Weight w (normalized) | K1: 1. Likelihood (λi\lambda_iλi​) | X1: 3. Exposure (ϵi\epsilon_iϵi​)
A2: Av | B2: 0.4 | C2: 1 | D2: 1 | E2: 0.7 | F2: 0.5 | G2: =B2*C2*D2*E2*F2 -> 0.14 | H2: =G2/SUM(G2:G5) -> 0.37807183
A3: Phy | B3: 0.4 | C3: 0.7 | D3: 1 | E3: 0.7 | F3: 0.5 | G3: =B3*C3*D3*E3*F3 -> 0.098 | H3: =G3/SUM(G2:G5) -> 0.26465028 | K3: What it is: Probability that an adverse event occurs for objective oio_ioi​. | X3: What it is: Attack surface or vulnerability level for that objective.
A4: AM | B4: 0.6 | C4: 0.5 | D4: 0.7 | E4: 0.7 | F4: 0.5 | G4: =B4*C4*D4*E4*F4 -> 0.0735 | H4: =G4/SUM(G2:G5) -> 0.19848771 | K4: How to estimate: | X4: How to estimate:
A5: CIA | B5: 0.7 | C5: 0.4 | D5: 0.6 | E5: 0.7 | F5: 0.5 | G5: =B5*C5*D5*E5*F5 -> 0.0588 | H5: =G5/SUM(G2:G5) -> 0.15879017 | K5: Use historical incident frequency (e.g., number of outages per year). | X5: Count exposed assets or open vulnerabilities.
K6: Threat intelligence (attack frequency for similar environments). | X6: Use CVSS or similar scoring.
K7: Normalize to [0,1]: | X7: Normalize:
K8: λi=observed frequencymax expected frequency\lambda_i = \frac{\text{observed frequency}}{\text{max expected frequency}}λi​=max expected frequencyobserved frequency​ | X8: \epsilon_i = \frac{\text{# exposed assets}}{\text{total assets}}
K12: 2. Impact (ιi\iota_iιi​) | X12: 4. Assurance (aia_iai​)
K14: What it is: Severity of consequences if the event occurs (financial, operational, regulatory). | X14: What it is: Confidence in your measurements and controls.
K15: How to estimate: | X15: How to estimate:
K16: Quantify potential loss (e.g., $ impact or downtime hours). | X16: Based on audit results or monitoring coverage.
K17: Map to scale [0,1]: | X17: High assurance → close to 1; low assurance → closer to 0.
K18: ιi=estimated lossworst-case loss\iota_i = \frac{\text{estimated loss}}{\text{worst-case loss}}ιi​=worst-case lossestimated loss​ | X18: Example: If 80% of controls are verified, ai=0.8a_i = 0.8ai​=0.8.
X22: 5. Localization (ℓi(s)\ell_i^{(s)}ℓi(s)​)
X24: What it is: Site-specific scaling factor (e.g., criticality of that site).
X25: How to estimate:
X26: Assign >1 for critical sites, <1 for less critical.
X27: Example: HQ = 1.5, small branch = 0.8.
L29: Objective 1 — Availability of Infrastructure (Av) | W29: Objective 3 — Auditability & Traceability (AM)
L31: Parameter | M31: Value | N31: Justification | W31: Parameter | X31: Value | Y31: Justification
L32: Likelihood ( \lambda_{Av} ) | M32: 0.75 | N32: Power failures, cooling incidents, network outages and ransomware-driven outages are frequent in datacenters. Public incident databases (ENISA, Uptime Institute) show high occurrence. | W32: Likelihood ( \lambda_{AM} ) | X32: 0.60 | Y32: Audit failures, missing logs, or insufficient traceability are common findings in audits and incidents.
L33: Impact ( \iota_{Av} ) | M33: 0.90 | N33: Downtime directly affects SLAs, penalties, reputational damage, and customer churn. Financial impact is immediate and high. | W33: Impact ( \iota_{AM} ) | X33: 0.65 | Y33: Poor traceability rarely causes immediate outages, but increases regulatory, forensic, and legal exposure.
L34: Exposure ( \epsilon_{Av} ) | M34: 0.80 | N34: Availability depends on exposed components: network edge, power systems, remote management, OT/ICS interfaces. | W34: Exposure ( \epsilon_{AM} ) | X34: 0.60 | Y34: Logging systems span many assets, identities, and access paths.
L35: Assurance ( a_{Av} ) | M35: 0.85 | N35: Availability metrics (uptime, MTTR, monitoring) are well-instrumented and auditable. High confidence in data. | W35: Assurance ( a_{AM} ) | X35: 0.75 | Y35: Log coverage and SIEM metrics provide reasonable confidence, but completeness is hard to prove.
L36: Localization ( \ell_{Av} ) | M36: 1.0 | N36: No site-specific amplification assumed (baseline site). | W36: Localization ( \ell_{AM} ) | X36: 1.0 | Y36: No amplification assumed.
L38: [ | W38: [
L39: R_{Av} = 0.75 \times 0.90 \times 0.80 \times 0.85 \times 1.0 = 0.459 | W39: R_{AM} = 0.60 \times 0.65 \times 0.60 \times 0.75 = 0.176
L40: ] | W40: ]
L44: Objective 2 — Physical Safety & Security (Phy) | W44: Objective 4 — Confidentiality, Integrity & Availability of Data (CIA)
L46: Parameter | M46: Value | N46: Justification | W46: Parameter | X46: Value | Y46: Justification
L47: Likelihood ( \lambda_{Phy} ) | M47: 0.40 | N47: Physical intrusions or sabotage are rarer than cyber events, especially in controlled datacenters. | W47: Likelihood ( \lambda_{CIA} ) | X47: 0.55 | Y47: Data breaches and integrity incidents are frequent but often mitigated by layered controls.
L48: Impact ( \iota_{Phy} ) | M48: 0.85 | N48: Physical breaches can cause safety incidents, asset loss, regulatory consequences, or cascading outages. | W48: Impact ( \iota_{CIA} ) | X48: 0.95 | Y48: Data compromise triggers GDPR penalties, client lawsuits, and contractual termination.
L49: Exposure ( \epsilon_{Phy} ) | M49: 0.50 | N49: Physical perimeters are limited in number and access points are controlled. | W49: Exposure ( \epsilon_{CIA} ) | X49: 0.75 | Y49: Data flows across networks, storage, backups, APIs, and third parties.
L50: Assurance ( a_{Phy} ) | M50: 0.70 | N50: Physical controls are audited, but blind spots exist (tailgating, insider threats). | W50: Assurance ( a_{CIA} ) | X50: 0.70 | Y50: Detection of data exfiltration or integrity loss is imperfect.
L51: Localization ( \ell_{Phy} ) | M51: 1.0 | N51: Standard threat environment. | W51: Localization ( \ell_{CIA} ) | X51: 1.0 | Y51: Baseline assumption.
L53: [ | W53: [
L54: R_{Phy} = 0.40 \times 0.85 \times 0.50 \times 0.70 = 0.119 | W54: R_{CIA} = 0.55 \times 0.95 \times 0.75 \times 0.70 = 0.274
L55: ] | W55: ]
Q59: Normalized Objective Weights
...

Sheet Topic Effectiveness
A1: Beta | B1: 0.7
A2: Topic | B2: r_Av | C2: r_Phy | D2: r_AM | E2: r_CIA | F2: v_j | G2: u_Av | H2: u_Phy | I2: u_AM | J2: u_CIA | K2: eta_Av | L2: eta_Phy | M2: eta_AM | N2: eta_CIA | Q2: rijr_{ij}rij​: Structural Relevance | AA2: What does β represent?
A3: Network Security | B3: 0.8 | C3: 0.2 | D3: 0.3 | E3: 0.9 | F3: 0.8 | G3: 0.9 | H3: 0.1 | I3: 0.4 | J3: 0.7 | K3: =$B$1*B3 + (1-$B$1)*F3*G3 -> 0.776 | L3: =$B$1*C3 + (1-$B$1)*F3*H3 -> 0.164 | M3: =$B$1*D3 + (1-$B$1)*F3*I3 -> 0.306 | N3: =$B$1*E3 + (1-$B$1)*F3*J3 -> 0.798
A4: Identity and Access Management (IAM) | B4: 0.6 | C4: 0.2 | D4: 0.9 | E4: 0.8 | F4: 0.85 | G4: 0.6 | H4: 0.4 | I4: 0.9 | J4: 0.9 | K4: =$B$1*B4 + (1-$B$1)*F4*G4 -> 0.573 | L4: =$B$1*C4 + (1-$B$1)*F4*H4 -> 0.242 | M4: =$B$1*D4 + (1-$B$1)*F4*I4 -> 0.8595 | N4: =$B$1*E4 + (1-$B$1)*F4*J4 -> 0.7895 | Q4: What it is: How strongly topic tjt_jtj​ is conceptually aligned with objective oio_ioi​. | AA4: It controls the relative importance of:
A5: Cryptography | B5: 0.4 | C5: 0.1 | D5: 0.4 | E5: 0.9 | F5: 0.4 | G5: 0.3 | H5: 0.1 | I5: 0.5 | J5: 0.95 | K5: =$B$1*B5 + (1-$B$1)*F5*G5 -> 0.316 | L5: =$B$1*C5 + (1-$B$1)*F5*H5 -> 0.082 | M5: =$B$1*D5 + (1-$B$1)*F5*I5 -> 0.34 | N5: =$B$1*E5 + (1-$B$1)*F5*J5 -> 0.744 | Q5: Example: Identity & Access Management (IAM) is highly relevant to “Auditability” (AM), so rAM,IAMr_{AM,IAM}rAM,IAM​ ≈ 0.9. | AA5: Structural relevance (rijr_{ij}rij​): how well the topic aligns with the objective conceptually.
A6: Security Operations | B6: 0.9 | C6: 0.3 | D6: 0.8 | E6: 0.6 | F6: 0.75 | G6: 0.8 | H6: 0.4 | I6: 0.8 | J6: 0.7 | K6: =$B$1*B6 + (1-$B$1)*F6*G6 -> 0.81 | L6: =$B$1*C6 + (1-$B$1)*F6*H6 -> 0.3 | M6: =$B$1*D6 + (1-$B$1)*F6*I6 -> 0.74 | N6: =$B$1*E6 + (1-$B$1)*F6*J6 -> 0.5775 | AA6: Vulnerability-driven term (vjuijv_j u_{ij}vj​uij​): how urgent and impactful the topic is based on current threat exposure.
A7: Security Awareness & Training | B7: 0.5 | C7: 0.2 | D7: 0.6 | E7: 0.5 | F7: 0.9 | G7: 0.6 | H7: 0.3 | I7: 0.7 | J7: 0.6 | K7: =$B$1*B7 + (1-$B$1)*F7*G7 -> 0.512 | L7: =$B$1*C7 + (1-$B$1)*F7*H7 -> 0.221 | M7: =$B$1*D7 + (1-$B$1)*F7*I7 -> 0.609 | N7: =$B$1*E7 + (1-$B$1)*F7*J7 -> 0.512 | Q7: How to estimate:
A8: Critical Infrastructure Security | B8: 0.95 | C8: 0.8 | D8: 0.4 | E8: 0.6 | F8: 0.9 | G8: 0.98 | H8: 0.9 | I8: 0.5 | J8: 0.2 | K8: =$B$1*B8 + (1-$B$1)*F8*G8 -> 0.9296 | L8: =$B$1*C8 + (1-$B$1)*F8*H8 -> 0.803 | M8: =$B$1*D8 + (1-$B$1)*F8*I8 -> 0.415 | N8: =$B$1*E8 + (1-$B$1)*F8*J8 -> 0.474 | Q8: Use mapping tables (e.g., NIST CSF subcategories → objectives). | AA8: So:
A9: Cyber Threat Intelligence | B9: 0.6 | C9: 0.2 | D9: 0.5 | E9: 0.4 | F9: 0.7 | G9: 0.7 | H9: 0.3 | I9: 0.6 | J9: 0.5 | K9: =$B$1*B9 + (1-$B$1)*F9*G9 -> 0.567 | L9: =$B$1*C9 + (1-$B$1)*F9*H9 -> 0.203 | M9: =$B$1*D9 + (1-$B$1)*F9*I9 -> 0.476 | N9: =$B$1*E9 + (1-$B$1)*F9*J9 -> 0.385 | Q9: Expert judgment or scoring (0–1 scale).
A10: Risk analysis | B10: 0.7 | C10: 0.95 | D10: 0.3 | E10: 0.2 | F10: 0 | G10: 0.5 | H10: 0.5 | I10: 0.5 | J10: 0.6 | K10: =$B$1*B10 + (1-$B$1)*F10*G10 -> 0.49 | L10: =$B$1*C10 + (1-$B$1)*F10*H10 -> 0.665 | M10: =$B$1*D10 + (1-$B$1)*F10*I10 -> 0.21 | N10: =$B$1*E10 + (1-$B$1)*F10*J10 -> 0.14 | Q10: Possible automation: text similarity between control descriptions and objective definitions. | AA10: β close to 1 → prioritize policy alignment (static relevance).
A11: Physical Security | B11: 0.1 | C11: 1 | D11: 0.7 | E11: 0.2 | F11: 0.6 | G11: 0.1 | H11: 1 | I11: 0.8 | J11: 0.7 | K11: =$B$1*B11 + (1-$B$1)*F11*G11 -> 0.088 | L11: =$B$1*C11 + (1-$B$1)*F11*H11 -> 0.88 | M11: =$B$1*D11 + (1-$B$1)*F11*I11 -> 0.634 | N11: =$B$1*E11 + (1-$B$1)*F11*J11 -> 0.266 | AA11: β close to 0 → prioritize dynamic vulnerability pressure.
A12: Supply Chain Security | B12: 0.7 | C12: 0.3 | D12: 0.6 | E12: 0.8 | F12: 0.7 | G12: 0.8 | H12: 0.4 | I12: 0.7 | J12: 0.9 | K12: =$B$1*B12 + (1-$B$1)*F12*G12 -> 0.658 | L12: =$B$1*C12 + (1-$B$1)*F12*H12 -> 0.294 | M12: =$B$1*D12 + (1-$B$1)*F12*I12 -> 0.567 | N12: =$B$1*E12 + (1-$B$1)*F12*J12 -> 0.749 | Q12: vjv_jvj​: Vulnerability Pressure
Q14: What it is: How urgent the topic is based on current threat exposure.
Q15: Example: If recent scans show many network vulnerabilities, vNetwork Securityv_{\text{Network Security}}vNetwork Security​ ≈ 0.8. | AA15: How to choose β?
Q17: How to estimate: | AA17: There are three practical approaches:
Q18: Vulnerability metrics (CVSS scores, number of open findings).
Q19: Threat intelligence (frequency of exploits in the wild). | AA19: 1. Policy-driven choice
Q20: Normalize to [0,1]: e.g., v_j = \frac{\text{#critical findings}}{\text{max observed}}.
AA21: If your organization values strategic alignment over short-term threat response, set β high (e.g., 0.7–0.8).
Q22: uiju_{ij}uij​: Utility of Mitigation | AA22: If you want a threat-driven prioritization, set β low (e.g., 0.2–0.3).
AA23: 2. Data-driven calibration
Q24: What it is: How much reducing vulnerabilities in topic tjt_jtj​ benefits objective oio_ioi​.
Q25: Example: Patching network flaws improves “Availability” more than “Confidentiality”. | AA25: Collect historical data: compare past incidents vs. relevance mapping.
AA26: Use regression or optimization to find β that best predicts risk reduction outcomes.
Q27: How to estimate: | AA27: 3. Scenario-based tuning
Q28: Expert judgment: assign higher utility where mitigation directly impacts the objective.
Q29: Data-driven: historical incident impact mapping (e.g., outages vs. network flaws). | AA29: Run sensitivity analysis: vary β from 0 to 1 and observe how rankings change.
Q30: Normalize to [0,1]. | AA30: Choose β that gives a balanced portfolio under your risk appetite.
Q34: 1. Network Security | AA34: 6. Critical Infrastructure Security (ICS/OT)
Q36: Parameter | R36: Value | S36: Justification | AA36: Parameter | AB36: Value | AC36: Justification
Q37: Vulnerability pressure (v_j) | R37: 0.80 | S37: Frequent CVEs, exposed perimeter services, DDoS, misconfigurations. | AA37: (v_j) | AB37: 0.90 | AC37: Legacy OT systems, high exploitability.
Q38: Utility (u_{Av}) | R38: 0.9 | S38: Directly prevents outages. | AA38: (u_{Av}) | AB38: 0.95 | AC38: Directly protects power, cooling, BMS.
Q39: Utility (u_{CIA}) | R39: 0.7 | S39: Reduces exfiltration and MITM. | AA39: (u_{Phy}) | AB39: 0.8 | AC39: Safety and physical continuity.
Q40: Utility (u_{AM}) | R40: 0.4 | S40: Indirect logging improvement.
Q41: Utility (u_{Phy}) | R41: 0.1 | S41: Minimal physical impact.
AA42: 7. Cyber Threat Intelligence (CTI)
Q44: 2. Identity & Access Management (IAM) | AA44: Parameter | AB44: Value | AC44: Justification
AA45: (v_j) | AB45: 0.55 | AC45: Depends on integration maturity.
Q46: Parameter | R46: Value | S46: Justification | AA46: (u_{Av}) | AB46: 0.6 | AC46: Proactive defense.
Q47: (v_j) | R47: 0.85 | S47: Credential abuse dominates breach root causes. | AA47: (u_{CIA}) | AB47: 0.6 | AC47: Anticipates campaigns.
...

Sheet Interdependency
B1: Network Security | C1: Identity and Access Management (IAM) | D1: Cryptography | E1: Security Operations | F1: Security Awareness & Training | G1: Critical Infrastructure Security | H1: Cyber Threat Intelligence | I1: Risk analysis | J1: Physical Security | K1: Supply Chain Security | U1: Matrix DDD: When values are positive or negative
A2: Network Security | B2: 0 | C2: 0.3 | D2: 0 | E2: 0.4 | F2: 0 | G2: 0.4 | H2: 0 | I2: 0 | J2: 0 | K2: 0
A3: Identity and Access Management (IAM) | B3: 0.25 | C3: 0 | D3: 0.2 | E3: 0.35 | F3: 0.3 | G3: 0 | H3: 0 | I3: 0.3 | J3: 0.4 | K3: 0 | U3: Positive Djk>0D_{jk} > 0Djk​>0
A4: Cryptography | B4: -0.05 | C4: 0.07 | D4: 0 | E4: 0.15 | F4: 0 | G4: 0 | H4: 0 | I4: 0 | J4: 0 | K4: 0.25 | U4: Means synergy: improving topic tkt_ktk​ makes topic tjt_jtj​ more effective.
A5: Security Operations | B5: -0.2 | C5: 0.4 | D5: 0 | E5: 0 | F5: 0.25 | G5: 0 | H5: 0.5 | I5: 0 | J5: 0 | K5: 0.3 | U5: Example: Strengthening Identity & Access Management (IAM) improves Security Operations because better IAM reduces incident complexity.
A6: Security Awareness & Training | B6: 0 | C6: 0.3 | D6: 0 | E6: 0.25 | F6: 0 | G6: 0 | H6: 0 | I6: 0.2 | J6: 0.15 | K6: 0.2 | U6: So DSecOps, IAM>0D_{\text{SecOps, IAM}} > 0DSecOps, IAM​>0.
A7: Critical Infrastructure Security | B7: 0.35 | C7: 0 | D7: 0 | E7: 0.3 | F7: 0 | G7: 0 | H7: 0 | I7: 0 | J7: 0.4 | K7: 0
A8: Cyber Threat Intelligence | B8: 0 | C8: 0 | D8: 0 | E8: 0.5 | F8: 0 | G8: 0 | H8: 0 | I8: 0.3 | J8: 0 | K8: 0.25 | U8: Negative Djk<0D_{jk} < 0Djk​<0
A9: Risk analysis | B9: 0 | C9: 0.3 | D9: 0 | E9: 0 | F9: 0.2 | G9: 0.25 | H9: 0.3 | I9: 0 | J9: 0.2 | K9: 0.5 | U9: Means overlap or redundancy: investing in topic tkt_ktk​ reduces the marginal benefit of topic tjt_jtj​.
A10: Physical Security | B10: 0 | C10: 0.4 | D10: 0 | E10: 0 | F10: 0.15 | G10: 0.4 | H10: 0 | I10: 0 | J10: 0 | K10: 0.2 | U10: Example: If you heavily invest in Network Security, adding more to Critical Infrastructure Security may have diminishing returns because both address similar attack vectors.
A11: Supply Chain Security | B11: 0 | C11: 0 | D11: 0.25 | E11: 0.3 | F11: 0.2 | G11: 0 | H11: 0.25 | I11: 0.5 | J11: 0.2 | K11: 0 | U11: So DInfraSec, NetSec<0D_{\text{InfraSec, NetSec}} < 0DInfraSec, NetSec​<0.
A13: Alpha | B13: 0.2 | U13: Zero Djk=0D_{jk} = 0Djk​=0
U14: Means independence: no significant interaction between topics.
A16: M=I + alpha*D | N16: Eta
A17: Topic | B17: Network Security | C17: Identity and Access Management (IAM) | D17: Cryptography | E17: Security Operations | F17: Security Awareness & Training | G17: Critical Infrastructure Security | H17: Cyber Threat Intelligence | I17: Risk analysis | J17: Physical Security | K17: Supply Chain Security | N17: eta_Av | O17: eta_Phy | P17: eta_AM | Q17: eta_CIA
A18: Network Security | B18: 1 | C18: =C2*$B$13 -> 0.06 | D18: =D2*$B$13 -> 0 | E18: =E2*$B$13 -> 0.08 | F18: =F2*$B$13 -> 0 | G18: =G2*$B$13 -> 0.08 | H18: =H2*$B$13 -> 0 | I18: =I2*$B$13 -> 0 | J18: =J2*$B$13 -> 0 | K18: =K2*$B$13 -> 0 | N18: ='Topic Effectiveness'!K3 -> 0.776 | O18: ='Topic Effectiveness'!L3 -> 0.164 | P18: ='Topic Effectiveness'!M3 -> 0.306 | Q18: ='Topic Effectiveness'!N3 -> 0.798 | U18: Alpha (α\alphaα): What it does
A19: Identity and Access Management (IAM) | B19: =B3*$B$13 -> 0.05 | C19: 1 | D19: =D3*$B$13 -> 0.04 | E19: =E3*$B$13 -> 0.07 | F19: =F3*$B$13 -> 0.06 | G19: =G3*$B$13 -> 0 | H19: =H3*$B$13 -> 0 | I19: =I3*$B$13 -> 0.06 | J19: =J3*$B$13 -> 0.08 | K19: =K3*$B$13 -> 0 | N19: ='Topic Effectiveness'!K4 -> 0.573 | O19: ='Topic Effectiveness'!L4 -> 0.242 | P19: ='Topic Effectiveness'!M4 -> 0.8595 | Q19: ='Topic Effectiveness'!N4 -> 0.7895
A20: Cryptography | B20: =B4*$B$13 -> -0.01 | C20: =C4*$B$13 -> 0.014 | D20: 1 | E20: =E4*$B$13 -> 0.03 | F20: =F4*$B$13 -> 0 | G20: =G4*$B$13 -> 0 | H20: =H4*$B$13 -> 0 | I20: =I4*$B$13 -> 0 | J20: =J4*$B$13 -> 0 | K20: =K4*$B$13 -> 0.05 | N20: ='Topic Effectiveness'!K5 -> 0.316 | O20: ='Topic Effectiveness'!L5 -> 0.082 | P20: ='Topic Effectiveness'!M5 -> 0.34 | Q20: ='Topic Effectiveness'!N5 -> 0.744 | U20: α∈[0,1]\alpha \in [0,1]α∈[0,1] is a global scaling factor for dependency effects.
A21: Security Operations | B21: =B5*$B$13 -> -0.04 | C21: =C5*$B$13 -> 0.08 | D21: =D5*$B$13 -> 0 | E21: 1 | F21: =F5*$B$13 -> 0.05 | G21: =G5*$B$13 -> 0 | H21: =H5*$B$13 -> 0.1 | I21: =I5*$B$13 -> 0 | J21: =J5*$B$13 -> 0 | K21: =K5*$B$13 -> 0.06 | N21: ='Topic Effectiveness'!K6 -> 0.81 | O21: ='Topic Effectiveness'!L6 -> 0.3 | P21: ='Topic Effectiveness'!M6 -> 0.74 | Q21: ='Topic Effectiveness'!N6 -> 0.5775 | U21: α=0\alpha = 0α=0 → ignore dependencies (pure additive model).
A22: Security Awareness & Training | B22: =B6*$B$13 -> 0 | C22: =C6*$B$13 -> 0.06 | D22: =D6*$B$13 -> 0 | E22: =E6*$B$13 -> 0.05 | F22: 1 | G22: =G6*$B$13 -> 0 | H22: =H6*$B$13 -> 0 | I22: =I6*$B$13 -> 0.04 | J22: =J6*$B$13 -> 0.03 | K22: =K6*$B$13 -> 0.04 | N22: ='Topic Effectiveness'!K7 -> 0.512 | O22: ='Topic Effectiveness'!L7 -> 0.221 | P22: ='Topic Effectiveness'!M7 -> 0.609 | Q22: ='Topic Effectiveness'!N7 -> 0.512 | U22: α=1\alpha = 1α=1 → apply full dependency matrix DDD.
A23: Critical Infrastructure Security | B23: =B7*$B$13 -> 0.07 | C23: =C7*$B$13 -> 0 | D23: =D7*$B$13 -> 0 | E23: =E7*$B$13 -> 0.06 | F23: =F7*$B$13 -> 0 | G23: 1 | H23: =H7*$B$13 -> 0 | I23: =I7*$B$13 -> 0 | J23: =J7*$B$13 -> 0.08 | K23: =K7*$B$13 -> 0 | N23: ='Topic Effectiveness'!K8 -> 0.9296 | O23: ='Topic Effectiveness'!L8 -> 0.803 | P23: ='Topic Effectiveness'!M8 -> 0.415 | Q23: ='Topic Effectiveness'!N8 -> 0.474 | U23: Typical choice: 0.2–0.5 to moderate the influence of synergies/overlaps without overwhelming the base effectiveness.
A24: Cyber Threat Intelligence | B24: =B8*$B$13 -> 0 | C24: =C8*$B$13 -> 0 | D24: =D8*$B$13 -> 0 | E24: =E8*$B$13 -> 0.1 | F24: =F8*$B$13 -> 0 | G24: =G8*$B$13 -> 0 | H24: 1 | I24: =I8*$B$13 -> 0.06 | J24: =J8*$B$13 -> 0 | K24: =K8*$B$13 -> 0.05 | N24: ='Topic Effectiveness'!K9 -> 0.567 | O24: ='Topic Effectiveness'!L9 -> 0.203 | P24: ='Topic Effectiveness'!M9 -> 0.476 | Q24: ='Topic Effectiveness'!N9 -> 0.385
A25: Risk analysis | B25: =B9*$B$13 -> 0 | C25: =C9*$B$13 -> 0.06 | D25: =D9*$B$13 -> 0 | E25: =E9*$B$13 -> 0 | F25: =F9*$B$13 -> 0.04 | G25: =G9*$B$13 -> 0.05 | H25: =H9*$B$13 -> 0.06 | I25: 1 | J25: =J9*$B$13 -> 0.04 | K25: =K9*$B$13 -> 0.1 | N25: ='Topic Effectiveness'!K10 -> 0.49 | O25: ='Topic Effectiveness'!L10 -> 0.665 | P25: ='Topic Effectiveness'!M10 -> 0.21 | Q25: ='Topic Effectiveness'!N10 -> 0.14
A26: Physical Security | B26: =B10*$B$13 -> 0 | C26: =C10*$B$13 -> 0.08 | D26: =D10*$B$13 -> 0 | E26: =E10*$B$13 -> 0 | F26: =F10*$B$13 -> 0.03 | G26: =G10*$B$13 -> 0.08 | H26: =H10*$B$13 -> 0 | I26: =I10*$B$13 -> 0 | J26: 1 | K26: =K10*$B$13 -> 0.04 | N26: ='Topic Effectiveness'!K11 -> 0.088 | O26: ='Topic Effectiveness'!L11 -> 0.88 | P26: ='Topic Effectiveness'!M11 -> 0.634 | Q26: ='Topic Effectiveness'!N11 -> 0.266
A27: Supply Chain Security | B27: =B11*$B$13 -> 0 | C27: =C11*$B$13 -> 0 | D27: =D11*$B$13 -> 0.05 | E27: =E11*$B$13 -> 0.06 | F27: =F11*$B$13 -> 0.04 | G27: =G11*$B$13 -> 0 | H27: =H11*$B$13 -> 0.05 | I27: =I11*$B$13 -> 0.1 | J27: =J11*$B$13 -> 0.04 | K27: 1 | N27: ='Topic Effectiveness'!K12 -> 0.658 | O27: ='Topic Effectiveness'!L12 -> 0.294 | P27: ='Topic Effectiveness'!M12 -> 0.567 | Q27: ='Topic Effectiveness'!N12 -> 0.749 | U27: Justification for Each Interdependency
U29: Below, each non-zero coefficient is explicitly justified.
A31: Eta'
A32: Topic | B32: eta_Av | C32: eta_Phy | D32: eta_AM | E32: eta_CIA
A33: Network Security | B33: {=MMULT(B18:K27,N18:Q27)} -> 0.949548 | C33: 0.26676 | D33: 0.44997 | E33: 0.92949 | U33: Network Security (T1) | AF33: Security Awareness (T5)
A34: Identity and Access Management (IAM) | B34: 0.7483 | C34: 0.39804 | D34: 1.04006 | E34: 0.959985
A35: Cryptography | B35: 0.373462 | C35: 0.107448 | D35: 0.399523 | E35: 0.801848 | U35: T1 ← T2 (IAM): +0.30 | AF35: T5 ← T2 (IAM): +0.30
A36: Security Operations | B36: 0.94658 | C36: 0.36179 | D36: 0.90859 | E36: 0.71778 | U36: Identity-aware networking (802.1X, NAC, ZTNA) improves segmentation effectiveness. | AF36: IAM training reinforces proper credential usage.
A37: Security Awareness & Training | B37: 0.63544 | C37: 0.31528 | D37: 0.74767 | E37: 0.631785
A38: Critical Infrastructure Security | B38: 1.03956 | C38: 0.90288 | D38: 0.53154 | E38: 0.58579 | U38: T1 ← T4 (SOC): +0.40 | AF38: T5 ← T4 (SOC): +0.25
A39: Cyber Threat Intelligence | B39: 0.7103 | C39: 0.2876 | D39: 0.59095 | E39: 0.4886 | U39: SOC tuning improves firewall rule monitoring and anomaly detection. | AF39: Incident feedback improves training relevance.
A40: Risk analysis | B40: 0.69468 | C40: 0.80529 | D40: 0.4173 | E40: 0.34019
A41: Physical Security | B41: 0.249888 | C41: 0.98199 | D41: 0.77691 | E41: 0.4124 | U41: T1 ← T6 (Critical Infrastructure): +0.40 | AF41: T5 ← T8 (Risk): +0.20
A42: Supply Chain Security | B42: 0.82375 | C42: 0.43679 | D42: 0.72292 | E42: 0.88522 | U42: OT network segmentation significantly benefits from secure network architecture. | AF42: Risk insights shape targeted training.
AF44: T5 ← T9 (Physical): +0.15
AF45: Physical security behavior improves with awareness.
...

Sheet Global Score
A1: Topic | B1: Score
A2: Network Security | B2: ='Risk Weights'!$H$2*Interdependency!B33 + 'Risk Weights'!$H$3*Interdependency!C33 + 'Risk Weights'!$H$4*Interdependency!D33 + 'Risk Weights'!$H$5*Interdependency!E33 -> 0.66650285 | C2: 5
A3: Identity and Access Management (IAM) | B3: ='Risk Weights'!$H$2*Interdependency!B34 + 'Risk Weights'!$H$3*Interdependency!C34 + 'Risk Weights'!$H$4*Interdependency!D34 + 'Risk Weights'!$H$5*Interdependency!E34 -> 0.74712786 | C3: 2
A4: Cryptography | B4: ='Risk Weights'!$H$2*Interdependency!B35 + 'Risk Weights'!$H$3*Interdependency!C35 + 'Risk Weights'!$H$4*Interdependency!D35 + 'Risk Weights'!$H$5*Interdependency!E35 -> 0.37625759
A5: Security Operations | B5: ='Risk Weights'!$H$2*Interdependency!B36 + 'Risk Weights'!$H$3*Interdependency!C36 + 'Risk Weights'!$H$4*Interdependency!D36 + 'Risk Weights'!$H$5*Interdependency!E36 -> 0.74794342 | C5: 3
A6: Security Awareness & Training | B6: ='Risk Weights'!$H$2*Interdependency!B37 + 'Risk Weights'!$H$3*Interdependency!C37 + 'Risk Weights'!$H$4*Interdependency!D37 + 'Risk Weights'!$H$5*Interdependency!E37 -> 0.57240546
A7: Critical Infrastructure Security | B7: ='Risk Weights'!$H$2*Interdependency!B38 + 'Risk Weights'!$H$3*Interdependency!C38 + 'Risk Weights'!$H$4*Interdependency!D38 + 'Risk Weights'!$H$5*Interdependency!E38 -> 0.83049766 | C7: 1
A8: Cyber Threat Intelligence | B8: ='Risk Weights'!$H$2*Interdependency!B39 + 'Risk Weights'!$H$3*Interdependency!C39 + 'Risk Weights'!$H$4*Interdependency!D39 + 'Risk Weights'!$H$5*Interdependency!E39 -> 0.53953904
A9: Risk analysis | B9: ='Risk Weights'!$H$2*Interdependency!B40 + 'Risk Weights'!$H$3*Interdependency!C40 + 'Risk Weights'!$H$4*Interdependency!D40 + 'Risk Weights'!$H$5*Interdependency!E40 -> 0.61260692
A10: Physical Security | B10: ='Risk Weights'!$H$2*Interdependency!B41 + 'Risk Weights'!$H$3*Interdependency!C41 + 'Risk Weights'!$H$4*Interdependency!D41 + 'Risk Weights'!$H$5*Interdependency!E41 -> 0.5740517
A11: Supply Chain Security | B11: ='Risk Weights'!$H$2*Interdependency!B42 + 'Risk Weights'!$H$3*Interdependency!C42 + 'Risk Weights'!$H$4*Interdependency!D42 + 'Risk Weights'!$H$5*Interdependency!E42 -> 0.71108824 | C11: 4
